<?xml version="1.0" ?>
<!-- =================================================================================== -->
<!-- |    This document was autogenerated by xacro from /home/vipul/ROS2/rhex_ws/src/rhex_description/urdf/rhex.xacro | -->
<!-- |    EDITING THIS FILE BY HAND IS NOT RECOMMENDED                                 | -->
<!-- =================================================================================== -->
<robot name="rhex">
  <material name="silver">
    <color rgba="0.700 0.700 0.700 1.000"/>
  </material>
  <transmission name="L_FR_tran">
    <type>transmission_interface/SimpleTransmission</type>
    <joint name="L_FR">
      <hardwareInterface>hardware_interface/EffortJointInterface</hardwareInterface>
    </joint>
    <actuator name="L_FR_actr">
      <hardwareInterface>hardware_interface/EffortJointInterface</hardwareInterface>
      <mechanicalReduction>1</mechanicalReduction>
    </actuator>
  </transmission>
  <transmission name="L_MR_tran">
    <type>transmission_interface/SimpleTransmission</type>
    <joint name="L_MR">
      <hardwareInterface>hardware_interface/EffortJointInterface</hardwareInterface>
    </joint>
    <actuator name="L_MR_actr">
      <hardwareInterface>hardware_interface/EffortJointInterface</hardwareInterface>
      <mechanicalReduction>1</mechanicalReduction>
    </actuator>
  </transmission>
  <transmission name="L_RR_tran">
    <type>transmission_interface/SimpleTransmission</type>
    <joint name="L_RR">
      <hardwareInterface>hardware_interface/EffortJointInterface</hardwareInterface>
    </joint>
    <actuator name="L_RR_actr">
      <hardwareInterface>hardware_interface/EffortJointInterface</hardwareInterface>
      <mechanicalReduction>1</mechanicalReduction>
    </actuator>
  </transmission>
  <transmission name="L_RL_tran">
    <type>transmission_interface/SimpleTransmission</type>
    <joint name="L_RL">
      <hardwareInterface>hardware_interface/EffortJointInterface</hardwareInterface>
    </joint>
    <actuator name="L_RL_actr">
      <hardwareInterface>hardware_interface/EffortJointInterface</hardwareInterface>
      <mechanicalReduction>1</mechanicalReduction>
    </actuator>
  </transmission>
  <transmission name="L_ML_tran">
    <type>transmission_interface/SimpleTransmission</type>
    <joint name="L_ML">
      <hardwareInterface>hardware_interface/EffortJointInterface</hardwareInterface>
    </joint>
    <actuator name="L_ML_actr">
      <hardwareInterface>hardware_interface/EffortJointInterface</hardwareInterface>
      <mechanicalReduction>1</mechanicalReduction>
    </actuator>
  </transmission>
  <transmission name="L_FL_tran">
    <type>transmission_interface/SimpleTransmission</type>
    <joint name="L_FL">
      <hardwareInterface>hardware_interface/EffortJointInterface</hardwareInterface>
    </joint>
    <actuator name="L_FL_actr">
      <hardwareInterface>hardware_interface/EffortJointInterface</hardwareInterface>
      <mechanicalReduction>1</mechanicalReduction>
    </actuator>
  </transmission>
  <gazebo reference="base_link">
    <material>Gazebo/Silver</material>
    <mu1>0.2</mu1>
    <mu2>0.2</mu2>
    <selfCollide>true</selfCollide>
    <gravity>true</gravity>
  </gazebo>
  <gazebo reference="leg_FR_1">
    <material>Gazebo/Silver</material>
    <mu1>0.2</mu1>
    <mu2>0.2</mu2>
    <selfCollide>true</selfCollide>
  </gazebo>
  <gazebo reference="leg_MR_1">
    <material>Gazebo/Silver</material>
    <mu1>0.2</mu1>
    <mu2>0.2</mu2>
    <selfCollide>true</selfCollide>
  </gazebo>
  <gazebo reference="leg_RR_1">
    <material>Gazebo/Silver</material>
    <mu1>0.2</mu1>
    <mu2>0.2</mu2>
    <selfCollide>true</selfCollide>
  </gazebo>
  <gazebo reference="leg_RL_1">
    <material>Gazebo/Silver</material>
    <mu1>0.2</mu1>
    <mu2>0.2</mu2>
    <selfCollide>true</selfCollide>
  </gazebo>
  <gazebo reference="leg_ML_1">
    <material>Gazebo/Silver</material>
    <mu1>0.2</mu1>
    <mu2>0.2</mu2>
    <selfCollide>true</selfCollide>
  </gazebo>
  <gazebo reference="leg_FL_1">
    <material>Gazebo/Silver</material>
    <mu1>0.2</mu1>
    <mu2>0.2</mu2>
    <selfCollide>true</selfCollide>
  </gazebo>
  <!-- ros2_control block - REQUIRED for controller_manager -->
  <ros2_control name="RHexSystem" type="system">
    <hardware>
      <!-- for Jazzy + Gazebo Harmonic (gz-sim / ignition) -->
      <plugin>gz_ros2_control/GazeboSimSystem</plugin>
    </hardware>
    <!-- Declare each actuated joint exactly as named in your URDF -->
    <joint name="L_FL">
      <command_interface name="position"/>
      <state_interface name="position"/>
      <state_interface name="velocity"/>
    </joint>
    <joint name="L_FR">
      <command_interface name="position"/>
      <state_interface name="position"/>
      <state_interface name="velocity"/>
    </joint>
    <joint name="L_ML">
      <command_interface name="position"/>
      <state_interface name="position"/>
      <state_interface name="velocity"/>
    </joint>
    <joint name="L_MR">
      <command_interface name="position"/>
      <state_interface name="position"/>
      <state_interface name="velocity"/>
    </joint>
    <joint name="L_RL">
      <command_interface name="position"/>
      <state_interface name="position"/>
      <state_interface name="velocity"/>
    </joint>
    <joint name="L_RR">
      <command_interface name="position"/>
      <state_interface name="position"/>
      <state_interface name="velocity"/>
    </joint>
  </ros2_control>
  <gazebo>
    <plugin filename="libgz_ros2_control-system.so" name="gz_ros2_control::GazeboSimROS2ControlPlugin">
      <robotNamespace>/rhex</robotNamespace>
      <parameters>/home/vipul/ROS2/rhex_ws/install/rhex_control/share/rhex_control/config/rhex_controller.yaml</parameters>
    </plugin>
  </gazebo>
  <link name="footprint"/>
  <link name="base_link">
    <inertial>
      <origin rpy="0 0 0" xyz="0.00026976113326567376 0.0 0.2"/>
      <mass value="3.703374358474152"/>
      <inertia ixx="0.020087" ixy="-0.0" ixz="-0.0" iyy="0.090417" iyz="0.0" izz="0.108396"/>
    </inertial>
    <visual>
      <origin rpy="0 0 0" xyz="0 0 0.2"/>
      <geometry>
        <mesh filename="package://rhex_description/meshes/base_link.stl" scale="0.001 0.001 0.001"/>
      </geometry>
      <material name="silver"/>
    </visual>
    <collision>
      <origin rpy="0 0 0" xyz="0 0 0.2"/>
      <geometry>
        <mesh filename="package://rhex_description/meshes/base_link.stl" scale="0.001 0.001 0.001"/>
      </geometry>
    </collision>
  </link>
  <joint name="base_joint" type="fixed">
    <parent link="footprint"/>
    <child link="base_link"/>
  </joint>
  <link name="leg_FR_1">
    <inertial>
      <origin rpy="0 0 0" xyz="-0.0604811121285076 0.0075000000000000205 -0.09500000000000028"/>
      <mass value="0.024174555469373752"/>
      <inertia ixx="0.00011" ixy="0.0" ixz="0.0" iyy="0.00013" iyz="-0.0" izz="2.1e-05"/>
    </inertial>
    <visual>
      <origin rpy="0 0 0" xyz="-0.21 -0.102 -0.0"/>
      <geometry>
        <mesh filename="package://rhex_description/meshes/leg_FR_1.stl" scale="0.001 0.001 0.001"/>
      </geometry>
      <material name="silver"/>
    </visual>
    <collision>
      <origin rpy="0 0 0" xyz="-0.21 -0.102 -0.0"/>
      <geometry>
        <mesh filename="package://rhex_description/meshes/leg_FR_1.stl" scale="0.001 0.001 0.001"/>
      </geometry>
    </collision>
  </link>
  <link name="leg_MR_1">
    <inertial>
      <origin rpy="0 0 0" xyz="-0.06048111212850748 0.007499999999999868 -0.09500000000000028"/>
      <mass value="0.024174555469373752"/>
      <inertia ixx="0.00011" ixy="0.0" ixz="0.0" iyy="0.00013" iyz="0.0" izz="2.1e-05"/>
    </inertial>
    <visual>
      <origin rpy="0 0 0" xyz="-0.0 -0.117 -0.0"/>
      <geometry>
        <mesh filename="package://rhex_description/meshes/leg_MR_1.stl" scale="0.001 0.001 0.001"/>
      </geometry>
      <material name="silver"/>
    </visual>
    <collision>
      <origin rpy="0 0 0" xyz="-0.0 -0.117 -0.0"/>
      <geometry>
        <mesh filename="package://rhex_description/meshes/leg_MR_1.stl" scale="0.001 0.001 0.001"/>
      </geometry>
    </collision>
  </link>
  <link name="leg_RR_1">
    <inertial>
      <origin rpy="0 0 0" xyz="-0.06048111212850768 0.007499999999999993 -0.09500000000000028"/>
      <mass value="0.02417455546937379"/>
      <inertia ixx="0.00011" ixy="0.0" ixz="0.0" iyy="0.00013" iyz="-0.0" izz="2.1e-05"/>
    </inertial>
    <visual>
      <origin rpy="0 0 0" xyz="0.21 -0.102 -0.0"/>
      <geometry>
        <mesh filename="package://rhex_description/meshes/leg_RR_1.stl" scale="0.001 0.001 0.001"/>
      </geometry>
      <material name="silver"/>
    </visual>
    <collision>
      <origin rpy="0 0 0" xyz="0.21 -0.102 -0.0"/>
      <geometry>
        <mesh filename="package://rhex_description/meshes/leg_RR_1.stl" scale="0.001 0.001 0.001"/>
      </geometry>
    </collision>
  </link>
  <link name="leg_RL_1">
    <inertial>
      <origin rpy="0 0 0" xyz="-0.06048111212850768 -0.0075000000000000205 -0.09500000000000028"/>
      <mass value="0.02417455546937379"/>
      <inertia ixx="0.00011" ixy="0.0" ixz="0.0" iyy="0.00013" iyz="0.0" izz="2.1e-05"/>
    </inertial>
    <visual>
      <origin rpy="0 0 0" xyz="0.21 0.102 -0.0"/>
      <geometry>
        <mesh filename="package://rhex_description/meshes/leg_RL_1.stl" scale="0.001 0.001 0.001"/>
      </geometry>
      <material name="silver"/>
    </visual>
    <collision>
      <origin rpy="0 0 0" xyz="0.21 0.102 -0.0"/>
      <geometry>
        <mesh filename="package://rhex_description/meshes/leg_RL_1.stl" scale="0.001 0.001 0.001"/>
      </geometry>
    </collision>
  </link>
  <link name="leg_ML_1">
    <inertial>
      <origin rpy="0 0 0" xyz="-0.06048111212850748 -0.007499999999999882 -0.09500000000000028"/>
      <mass value="0.024174555469373752"/>
      <inertia ixx="0.00011" ixy="-0.0" ixz="0.0" iyy="0.00013" iyz="-0.0" izz="2.1e-05"/>
    </inertial>
    <visual>
      <origin rpy="0 0 0" xyz="-0.0 0.117 -0.0"/>
      <geometry>
        <mesh filename="package://rhex_description/meshes/leg_ML_1.stl" scale="0.001 0.001 0.001"/>
      </geometry>
      <material name="silver"/>
    </visual>
    <collision>
      <origin rpy="0 0 0" xyz="-0.0 0.117 -0.0"/>
      <geometry>
        <mesh filename="package://rhex_description/meshes/leg_ML_1.stl" scale="0.001 0.001 0.001"/>
      </geometry>
    </collision>
  </link>
  <link name="leg_FL_1">
    <inertial>
      <origin rpy="0 0 0" xyz="-0.0604811121285076 -0.007500000000000076 -0.09500000000000028"/>
      <mass value="0.024174555469373752"/>
      <inertia ixx="0.00011" ixy="-0.0" ixz="0.0" iyy="0.00013" iyz="0.0" izz="2.1e-05"/>
    </inertial>
    <visual>
      <origin rpy="0 0 0" xyz="-0.21 0.102 -0.0"/>
      <geometry>
        <mesh filename="package://rhex_description/meshes/leg_FL_1.stl" scale="0.001 0.001 0.001"/>
      </geometry>
      <material name="silver"/>
    </visual>
    <collision>
      <origin rpy="0 0 0" xyz="-0.21 0.102 -0.0"/>
      <geometry>
        <mesh filename="package://rhex_description/meshes/leg_FL_1.stl" scale="0.001 0.001 0.001"/>
      </geometry>
    </collision>
  </link>
  <joint name="L_FR" type="continuous">
    <origin rpy="0 0 0" xyz="0.21 0.102 0.2"/>
    <parent link="base_link"/>
    <child link="leg_FR_1"/>
    <axis xyz="0.0 1.0 0.0"/>
    <limit effort="30" velocity="4"/>
    <joint_properties damping="1.0" friction="1.0"/>
  </joint>
  <joint name="L_MR" type="continuous">
    <origin rpy="0 0 0" xyz="0.0 0.117 0.2"/>
    <parent link="base_link"/>
    <child link="leg_MR_1"/>
    <axis xyz="0.0 1.0 0.0"/>
    <limit effort="30" velocity="4"/>
    <joint_properties damping="1.0" friction="1.0"/>
  </joint>
  <joint name="L_RR" type="continuous">
    <origin rpy="0 0 0" xyz="-0.21 0.102 0.2"/>
    <parent link="base_link"/>
    <child link="leg_RR_1"/>
    <axis xyz="0.0 1.0 0.0"/>
    <limit effort="30" velocity="4"/>
    <joint_properties damping="1.0" friction="1.0"/>
  </joint>
  <joint name="L_RL" type="continuous">
    <origin rpy="0 0 0" xyz="-0.21 -0.102 0.2"/>
    <parent link="base_link"/>
    <child link="leg_RL_1"/>
    <axis xyz="0.0 -1.0 0.0"/>
    <limit effort="30" velocity="4"/>
    <joint_properties damping="1.0" friction="1.0"/>
  </joint>
  <joint name="L_ML" type="continuous">
    <origin rpy="0 0 0" xyz="0.0 -0.117 0.2"/>
    <parent link="base_link"/>
    <child link="leg_ML_1"/>
    <axis xyz="0.0 -1.0 0.0"/>
    <limit effort="30" velocity="4"/>
    <joint_properties damping="1.0" friction="1.0"/>
  </joint>
  <joint name="L_FL" type="continuous">
    <origin rpy="0 0 0" xyz="0.21 -0.102 0.2"/>
    <parent link="base_link"/>
    <child link="leg_FL_1"/>
    <axis xyz="0.0 -1.0 0.0"/>
    <limit effort="30" velocity="4"/>
    <joint_properties damping="1.0" friction="1.0"/>
  </joint>
</robot>
